Workbook

Sheet Instrucciones
A1: Estructura de Costos — Milanesería
A3: Cómo usar esta planilla
A5: 1. | B5: Cada milanesa tiene su propia receta en la hoja 'Recetas', con sus insumos específicos (cantidades pensadas para 1 kg de carne cruda). Hay filas libres por si sumás ingredientes.
A6: 2. | B6: Los costos que comparten TODAS las milanesas (huevo, sal, envasado, comisión, descarte) están en 'Costos Generales' — se suman automáticamente al costo de cada receta.
A7: 3. | B7: En cada receta cargás el 'Peso final del lote rebozado' (ej: 1 kg de carne + empanado rinde entre 1,30 kg y 1,40 kg de milanesas, ¡un 30% a 40% más de peso!). De ahí se calculan las unidades reales por lote.
A8: 4. | B8: El 'Costo Final por Milanesa' de cada receta (celda verde) se linkea solo a 'Precios y Márgenes' — ahí cargás el precio de venta de cada una.
A9: 5. | B9: Cuando agregues una receta nueva, pasámela y te armo el bloque en 'Recetas' + su fila en 'Precios y Márgenes'.
A11: Referencia de colores
B13: Celda para completar (dato tuyo)
B14: Total fijo de una lista (siempre arriba, no se mueve)
B15: Celda calculada con fórmula (no tocar)
B16: Totales / resultados clave generales

Sheet Costos Fijos
A1: Costos Fijos Mensuales
A3: TOTAL COSTOS FIJOS MENSUALES | B3: =SUM(B6:B205) -> 1765000
A5: Concepto | B5: Costo Mensual | C5: Notas
A6: Alquiler | B6: 400000
A7: Expensas / ABL | B7: 60000
A8: Luz | B8: 90000
A9: Gas | B9: 70000 | C9: Puede ser alto si usás freidora a gas
A10: Agua | B10: 15000
A11: Internet | B11: 25000
A12: Sueldos fijos | B12: 900000 | C12: Personal en relación de dependencia
A13: Monotributo / Impuestos | B13: 80000
A14: Contador | B14: 60000
A15: Seguro del local | B15: 20000
A16: Matafuegos / Fumigación | B16: 15000 | C16: Prorrateado mensual si se paga anual
A17: Otros | B17: 30000

Sheet Capital Aportado
A1: Capital Aportado e Inversión Inicial
A3: Toda la inversión inicial se paga AL CONTADO — este negocio no financia compras ni toma deuda.
A5: A) Inversión Inicial (pago único, al contado)
A6: TOTAL INVERSIÓN INICIAL | B6: =SUM(B8:B157) -> 2060000
A7: Concepto | B7: Monto | C7: Notas
A8: Heladera / freezer | B8: 350000
A9: Anafe / cocina | B9: 180000
A10: Campana extractora | B10: 90000
A11: Máquina de fileteado / ablandadora | B11: 220000 | C11: Si vas a fabricar vos mismo
A12: Mesada de acero inoxidable / rebozado | B12: 120000
A13: Vitrina / mostrador | B13: 150000
A14: Mobiliario general | B14: 100000
A15: Adecuación del local (pintura, instalación eléctrica, etc.) | B15: 200000
A16: Habilitación municipal / bromatología | B16: 60000
A17: Cartelería / identidad de marca | B17: 40000
A18: Envasadora al vacío | B18: 280000
A19: Stock inicial de mercadería | B19: 150000
A20: Imprevistos / contingencia | B20: 120000 | C20: Recomendado: 10-15% del total
A159: B) Capital de Trabajo Inicial (colchón para primeros meses)
A160: Meses de costos fijos a cubrir antes de alcanzar el punto de equilibrio | B160: 2
A161: Costos fijos mensuales (de la hoja 'Costos Fijos') | B161: ='Costos Fijos'!B3 -> 1765000
A162: TOTAL CAPITAL DE TRABAJO INICIAL | B162: =B160*B161 -> 3530000
A164: TOTAL DE FONDOS NECESARIOS (Inversión + Capital de trabajo) | B164: =B6+B162 -> 5590000
A167: C) Aportes de Capital (socios / capital propio — sin financiamiento)
A168: TOTAL CAPITAL APORTADO | B168: =SUM(B170:B219) -> 2000000
A169: Aportante | B169: Monto aportado | C169: Notas
A170: Socio 1 | B170: 1200000
A171: Socio 2 | B171: 800000
A221: D) Verificación
A222: Total Capital Aportado | B222: =B168 -> 2000000
A223: Total de Fondos Necesarios | B223: =B164 -> 5590000
A224: Diferencia (Excedente / Faltante) | B224: =B222-B223 -> -3590000
A225: Estado | B225: =IF(B224>=0,"Capital suficiente ✓","FALTAN FONDOS ✗") -> FALTAN FONDOS ✗

Sheet Costos Generales
A1: Costos Generales (compartidos por todas las milanesas)
A3: A) Costos Generales POR LOTE (por kg de carne procesada)
A4: TOTAL GENERALES POR LOTE | E4: =SUM(E6:E35) -> 576.2
A5: Insumo | B5: Cantidad | C5: Unidad | D5: Costo unitario ($ por la unidad elegida) | E5: Costo de la línea
A6: Huevo | B6: 2 | C6: unidades | D6: 161.1 | E6: =IF(OR(B6="",D6=""),0,B6*D6) -> 322.2
A7: Sal | B7: 10 | C7: g | E7: =IF(OR(B7="",D7=""),0,B7*D7) -> 0
A8: Etiqueta | B8: 1 | C8: unidad | D8: 164 | E8: =IF(OR(B8="",D8=""),0,B8*D8) -> 164
A9: Bandeja | B9: 1 | C9: unidad | D9: 90 | E9: =IF(OR(B9="",D9=""),0,B9*D9) -> 90
C10: unidad | E10: =IF(OR(B10="",D10=""),0,B10*D10) -> 0
E11: =IF(OR(B11="",D11=""),0,B11*D11) -> 0
E12: =IF(OR(B12="",D12=""),0,B12*D12) -> 0
E13: =IF(OR(B13="",D13=""),0,B13*D13) -> 0
E14: =IF(OR(B14="",D14=""),0,B14*D14) -> 0
E15: =IF(OR(B15="",D15=""),0,B15*D15) -> 0
E16: =IF(OR(B16="",D16=""),0,B16*D16) -> 0
E17: =IF(OR(B17="",D17=""),0,B17*D17) -> 0
E18: =IF(OR(B18="",D18=""),0,B18*D18) -> 0
E19: =IF(OR(B19="",D19=""),0,B19*D19) -> 0
E20: =IF(OR(B20="",D20=""),0,B20*D20) -> 0
E21: =IF(OR(B21="",D21=""),0,B21*D21) -> 0
E22: =IF(OR(B22="",D22=""),0,B22*D22) -> 0
... E35: =IF(OR(B35="",D35=""),0,B35*D35) -> 0
A37: B) Parámetros generales
A38: Comisión tarjeta / app (%) | B38: 0.01
A39: % Margen de seguridad / desperdicio (opcional) | B39: 0

Sheet Recetas Pollo
A1: Recetas — Pollo
A3: Todas las cantidades de cada receta están pensadas para procesar 1 kg de carne cruda.
A5: Suprema Tradicional (Pollo)
A6: TOTAL INSUMOS ESPECÍFICOS (por kg de carne) | E6: =SUM(E8:E23) -> 0
A7: Insumo | B7: Cantidad | C7: Unidad | D7: Costo unitario | E7: Costo de la línea
A8: Oregano | B8: 2 | C8: g | E8: =IF(D8="",0,B8*D8) -> 0
A9: Provenzal | B9: 2 | C9: g | E9: =IF(D9="",0,B9*D9) -> 0
A10: Pechuga de pollo | B10: 1000 | C10: g
A11: Pan rayado | C11: g | E11: =IF(D11="",0,B11*D11) -> 0
A12: Rebozador | E12: =IF(OR(B12="",D12=""),0,B12*D12) -> 0
E13: =IF(OR(B13="",D13=""),0,B13*D13) -> 0
E14: =IF(OR(B14="",D14=""),0,B14*D14) -> 0
E15: =IF(OR(B15="",D15=""),0,B15*D15) -> 0
E16: =IF(OR(B16="",D16=""),0,B16*D16) -> 0
E17: =IF(OR(B17="",D17=""),0,B17*D17) -> 0
E18: =IF(OR(B18="",D18=""),0,B18*D18) -> 0
E19: =IF(OR(B19="",D19=""),0,B19*D19) -> 0
E20: =IF(OR(B20="",D20=""),0,B20*D20) -> 0
E21: =IF(OR(B21="",D21=""),0,B21*D21) -> 0
E22: =IF(OR(B22="",D22=""),0,B22*D22) -> 0
E23: =IF(OR(B23="",D23=""),0,B23*D23) -> 0
A24: Costo Insumos Específicos (por kg carne) | B24: =E6 -> 0
A25: Costos Generales por Lote (huevo, sal, etc.) | B25: ='Costos Generales'!E4 -> 576.2
A26: Costo Total del Lote (subtotal) | B26: =B24+B25 -> 576.2
A27: Peso final del lote rebozado (kg) [Ej: 1.35 a 1.40 kg por kg carne]
A28: Peso por milanesa (g)
A29: Unidades por lote | B29: =IF(OR(B27="",B28="",B28=0),0,(B27*1000)/B28) -> 0
A30: Costo del lote por unidad | B30: =IF(B29=0,0,B26/B29) -> 0
A31: COSTO FINAL POR MILANESA | B31: =B30/(1-'Costos Generales'!B39) -> 0
A34: Suprema Parmesana (Pollo)
A35: TOTAL INSUMOS ESPECÍFICOS (por kg de carne) | E35: =SUM(E37:E52) -> 0
A36: Insumo | B36: Cantidad | C36: Unidad | D36: Costo unitario | E36: Costo de la línea
A37: Oregano | B37: 2 | C37: g | E37: =IF(D37="",0,B37*D37) -> 0
A38: Pechuga de pollo | B38: 1000 | C38: g | E38: =IF(D38="",0,B38*D38) -> 0
A39: Pan rayado | C39: g | E39: =IF(D39="",0,B39*D39) -> 0
A40: Parmesano | C40: g | E40: =IF(D40="",0,B40*D40) -> 0
C41: g
B42: =0.7*B41 -> 0 | C42: g | E42: =IF(D42="",0,B42*D42) -> 0
B43: =0.3*B41 -> 0 | C43: g | E43: =IF(D43="",0,B43*D43) -> 0
E44: =IF(OR(B44="",D44=""),0,B44*D44) -> 0
...

Sheet Recetas Vaca
A1: Recetas — Vaca
A3: Todas las cantidades de cada receta están pensadas para procesar 1 kg de carne cruda.
A5: Vacuno Tradicional
A6: TOTAL INSUMOS ESPECÍFICOS (por kg de carne) | E6: =SUM(E8:E23) -> 0
A7: Insumo | B7: Cantidad | C7: Unidad | D7: Costo unitario | E7: Costo de la línea
C8: g | E8: =IF(D8="",0,B8*D8) -> 0
C9: g | E9: =IF(D9="",0,B9*D9) -> 0
C10: g
C11: g | E11: =IF(D11="",0,B11*D11) -> 0
E12: =IF(OR(B12="",D12=""),0,B12*D12) -> 0
E13: =IF(OR(B13="",D13=""),0,B13*D13) -> 0
E14: =IF(OR(B14="",D14=""),0,B14*D14) -> 0
E15: =IF(OR(B15="",D15=""),0,B15*D15) -> 0
E16: =IF(OR(B16="",D16=""),0,B16*D16) -> 0
E17: =IF(OR(B17="",D17=""),0,B17*D17) -> 0
E18: =IF(OR(B18="",D18=""),0,B18*D18) -> 0
E19: =IF(OR(B19="",D19=""),0,B19*D19) -> 0
E20: =IF(OR(B20="",D20=""),0,B20*D20) -> 0
E21: =IF(OR(B21="",D21=""),0,B21*D21) -> 0
E22: =IF(OR(B22="",D22=""),0,B22*D22) -> 0
E23: =IF(OR(B23="",D23=""),0,B23*D23) -> 0
A24: Costo Insumos Específicos (por kg carne) | B24: =E6 -> 0
A25: Costos Generales por Lote (huevo, sal, etc.) | B25: ='Costos Generales'!E4 -> 576.2
A26: Costo Total del Lote (subtotal) | B26: =B24+B25 -> 576.2
A27: Peso final del lote rebozado (kg) [Ej: 1.35 a 1.40 kg por kg carne]
A28: Peso por milanesa (g)
A29: Unidades por lote | B29: =IF(OR(B27="",B28="",B28=0),0,(B27*1000)/B28) -> 0
A30: Costo del lote por unidad | B30: =IF(B29=0,0,B26/B29) -> 0
A31: COSTO FINAL POR MILANESA | B31: =B30/(1-'Costos Generales'!B39) -> 0
A34: Vacuno Ahumado
A35: TOTAL INSUMOS ESPECÍFICOS (por kg de carne) | E35: =SUM(E37:E52) -> 0
A36: Insumo | B36: Cantidad | C36: Unidad | D36: Costo unitario | E36: Costo de la línea
A37: Pimenton ahumado | B37: 8 | C37: g | E37: =IF(D37="",0,B37*D37) -> 0
A38: Ajo en polvo | B38: 4 | C38: g | E38: =IF(D38="",0,B38*D38) -> 0
A39: Perejil | B39: 2 | C39: g | E39: =IF(D39="",0,B39*D39) -> 0
A40: Pimienta | B40: 2 | C40: g | E40: =IF(D40="",0,B40*D40) -> 0
A41: Mostaza | B41: 10 | C41: g | E41: =IF(D41="",0,B41*D41) -> 0
A42: Carne Vaca | B42: 1000 | C42: g | E42: =IF(D42="",0,B42*D42) -> 0
A43: Pan rayado | C43: g | E43: =IF(D43="",0,B43*D43) -> 0
A44: Rebozador | E44: =IF(OR(B44="",D44=""),0,B44*D44) -> 0
...

Sheet Recetas Cerdo
A1: Recetas — Cerdo
A3: Todas las cantidades de cada receta están pensadas para procesar 1 kg de carne cruda.
A5: Cerdo Tradicional
A6: TOTAL INSUMOS ESPECÍFICOS (por kg de carne) | E6: =SUM(E8:E23) -> 0
A7: Insumo | B7: Cantidad | C7: Unidad | D7: Costo unitario | E7: Costo de la línea
A8: Oregano | B8: 2 | C8: g | E8: =IF(D8="",0,B8*D8) -> 0
A9: Mostaza | B9: 10 | C9: g | E9: =IF(D9="",0,B9*D9) -> 0
A10: Cerdo | B10: 1000 | C10: g
A11: Pan rayado | C11: g | E11: =IF(D11="",0,B11*D11) -> 0
A12: Rebozador | C12: g | E12: =IF(OR(B12="",D12=""),0,B12*D12) -> 0
E13: =IF(OR(B13="",D13=""),0,B13*D13) -> 0
E14: =IF(OR(B14="",D14=""),0,B14*D14) -> 0
E15: =IF(OR(B15="",D15=""),0,B15*D15) -> 0
E16: =IF(OR(B16="",D16=""),0,B16*D16) -> 0
E17: =IF(OR(B17="",D17=""),0,B17*D17) -> 0
E18: =IF(OR(B18="",D18=""),0,B18*D18) -> 0
E19: =IF(OR(B19="",D19=""),0,B19*D19) -> 0
E20: =IF(OR(B20="",D20=""),0,B20*D20) -> 0
E21: =IF(OR(B21="",D21=""),0,B21*D21) -> 0
E22: =IF(OR(B22="",D22=""),0,B22*D22) -> 0
E23: =IF(OR(B23="",D23=""),0,B23*D23) -> 0
A24: Costo Insumos Específicos (por kg carne) | B24: =E6 -> 0
A25: Costos Generales por Lote (huevo, sal, etc.) | B25: ='Costos Generales'!E4 -> 576.2
A26: Costo Total del Lote (subtotal) | B26: =B24+B25 -> 576.2
A27: Peso final del lote rebozado (kg) [Ej: 1.35 a 1.40 kg por kg carne]
A28: Peso por milanesa (g)
A29: Unidades por lote | B29: =IF(OR(B27="",B28="",B28=0),0,(B27*1000)/B28) -> 0
A30: Costo del lote por unidad | B30: =IF(B29=0,0,B26/B29) -> 0
A31: COSTO FINAL POR MILANESA | B31: =B30/(1-'Costos Generales'!B39) -> 0
A34: Cerdo Ahumado
A35: TOTAL INSUMOS ESPECÍFICOS (por kg de carne) | E35: =SUM(E37:E52) -> 0
A36: Insumo | B36: Cantidad | C36: Unidad | D36: Costo unitario | E36: Costo de la línea
A37: Pimenton ahumado | B37: 8 | C37: g | E37: =IF(D37="",0,B37*D37) -> 0
A38: Ajo en polvo | B38: 4 | C38: g | E38: =IF(D38="",0,B38*D38) -> 0
A39: Perejil | B39: 2 | C39: g | E39: =IF(D39="",0,B39*D39) -> 0
A40: Pimienta | B40: 2 | C40: g | E40: =IF(D40="",0,B40*D40) -> 0
A41: Mostaza | B41: 10 | C41: g | E41: =IF(D41="",0,B41*D41) -> 0
A42: Cerdo | B42: 1000 | C42: g | E42: =IF(D42="",0,B42*D42) -> 0
A43: Pan rayado | C43: g | E43: =IF(D43="",0,B43*D43) -> 0
A44: Rebozador | C44: g | E44: =IF(OR(B44="",D44=""),0,B44*D44) -> 0
...

Sheet Precios y Márgenes
A1: Precios de Venta y Márgenes por Receta
A3: Receta | B3: Costo variable unitario | C3: Precio de venta | D3: Margen $ | E3: Margen % (sobre precio) | F3: Food cost %
A4: ='Recetas Pollo'!A5 -> Suprema Tradicional (Pollo) | B4: ='Recetas Pollo'!B31 -> 0 | D4: =IF(OR(C4="",C4=0),"",C4*(1-'Costos Generales'!B38)-B4) | E4: =IF(OR(D4="",C4="",C4=0),"",D4/C4) | F4: =IF(OR(C4="",C4=0),"",B4/C4)
A5: ='Recetas Pollo'!A34 -> Suprema Parmesana (Pollo) | B5: ='Recetas Pollo'!B60 -> 0 | D5: =IF(OR(C5="",C5=0),"",C5*(1-'Costos Generales'!B38)-B5) | E5: =IF(OR(D5="",C5="",C5=0),"",D5/C5) | F5: =IF(OR(C5="",C5=0),"",B5/C5)
A6: ='Recetas Pollo'!A63 -> Suprema Crunch (Pollo) | B6: ='Recetas Pollo'!B89 -> 0 | D6: =IF(OR(C6="",C6=0),"",C6*(1-'Costos Generales'!B38)-B6) | E6: =IF(OR(D6="",C6="",C6=0),"",D6/C6) | F6: =IF(OR(C6="",C6=0),"",B6/C6)
A7: ='Recetas Pollo'!A92 -> Suprema Rellena (Pollo) | B7: ='Recetas Pollo'!B118 -> 0 | D7: =IF(OR(C7="",C7=0),"",C7*(1-'Costos Generales'!B38)-B7) | E7: =IF(OR(D7="",C7="",C7=0),"",D7/C7) | F7: =IF(OR(C7="",C7=0),"",B7/C7)
A8: ='Recetas Pollo'!A121 -> Suprema Finas Hierbas (Pollo) | B8: ='Recetas Pollo'!B147 -> 0 | D8: =IF(OR(C8="",C8=0),"",C8*(1-'Costos Generales'!B38)-B8) | E8: =IF(OR(D8="",C8="",C8=0),"",D8/C8) | F8: =IF(OR(C8="",C8=0),"",B8/C8)
A9: ='Recetas Vaca'!A5 -> Vacuno Tradicional | B9: ='Recetas Vaca'!B31 -> 0 | D9: =IF(OR(C9="",C9=0),"",C9*(1-'Costos Generales'!B38)-B9) | E9: =IF(OR(D9="",C9="",C9=0),"",D9/C9) | F9: =IF(OR(C9="",C9=0),"",B9/C9)
A10: ='Recetas Vaca'!A34 -> Vacuno Ahumado | B10: ='Recetas Vaca'!B60 -> 0 | D10: =IF(OR(C10="",C10=0),"",C10*(1-'Costos Generales'!B38)-B10) | E10: =IF(OR(D10="",C10="",C10=0),"",D10/C10) | F10: =IF(OR(C10="",C10=0),"",B10/C10)
A11: ='Recetas Vaca'!A63 -> Vacuno Picante | B11: ='Recetas Vaca'!B89 -> 0 | D11: =IF(OR(C11="",C11=0),"",C11*(1-'Costos Generales'!B38)-B11) | E11: =IF(OR(D11="",C11="",C11=0),"",D11/C11) | F11: =IF(OR(C11="",C11=0),"",B11/C11)
A12: ='Recetas Vaca'!A92 -> Milanesa de Bola de Lomo Rellena (Vaca) | B12: ='Recetas Vaca'!B118 -> 0 | D12: =IF(OR(C12="",C12=0),"",C12*(1-'Costos Generales'!B38)-B12) | E12: =IF(OR(D12="",C12="",C12=0),"",D12/C12) | F12: =IF(OR(C12="",C12=0),"",B12/C12)
A13: ='Recetas Vaca'!A121 -> Milanesa Ajo y Perejil (Vaca) | B13: ='Recetas Vaca'!B147 -> 0 | D13: =IF(OR(C13="",C13=0),"",C13*(1-'Costos Generales'!B38)-B13) | E13: =IF(OR(D13="",C13="",C13=0),"",D13/C13) | F13: =IF(OR(C13="",C13=0),"",B13/C13)
A14: ='Recetas Cerdo'!A5 -> Cerdo Tradicional | B14: ='Recetas Cerdo'!B31 -> 0 | D14: =IF(OR(C14="",C14=0),"",C14*(1-'Costos Generales'!B38)-B14) | E14: =IF(OR(D14="",C14="",C14=0),"",D14/C14) | F14: =IF(OR(C14="",C14=0),"",B14/C14)
A15: ='Recetas Cerdo'!A34 -> Cerdo Ahumado | B15: ='Recetas Cerdo'!B60 -> 0 | D15: =IF(OR(C15="",C15=0),"",C15*(1-'Costos Generales'!B38)-B15) | E15: =IF(OR(D15="",C15="",C15=0),"",D15/C15) | F15: =IF(OR(C15="",C15=0),"",B15/C15)
A16: ='Recetas Cerdo'!A63 -> Cerdo Fugazzeta | B16: ='Recetas Cerdo'!B89 -> 0 | D16: =IF(OR(C16="",C16=0),"",C16*(1-'Costos Generales'!B38)-B16) | E16: =IF(OR(D16="",C16="",C16=0),"",D16/C16) | F16: =IF(OR(C16="",C16=0),"",B16/C16)
A17: ='Recetas Cerdo'!A92 -> Cerdo Mostaza y Miel | B17: ='Recetas Cerdo'!B118 -> 0 | D17: =IF(OR(C17="",C17=0),"",C17*(1-'Costos Generales'!B38)-B17) | E17: =IF(OR(D17="",C17="",C17=0),"",D17/C17) | F17: =IF(OR(C17="",C17=0),"",B17/C17)
A18: ='Recetas Cerdo'!A121 -> Indefinido | B18: ='Recetas Cerdo'!B147 -> 0 | D18: =IF(OR(C18="",C18=0),"",C18*(1-'Costos Generales'!B38)-B18) | E18: =IF(OR(D18="",C18="",C18=0),"",D18/C18) | F18: =IF(OR(C18="",C18=0),"",B18/C18)
A20: PROMEDIO | B20: =IFERROR(AVERAGEIFS(B4:B18,$C$4:$C$18,">0"),0) -> 0 | C20: =IFERROR(AVERAGEIFS(C4:C18,$C$4:$C$18,">0"),0) -> 0 | D20: =IFERROR(AVERAGEIFS(D4:D18,$C$4:$C$18,">0"),0) -> 0 | E20: =IFERROR(AVERAGEIFS(E4:E18,$C$4:$C$18,">0"),0) -> 0 | F20: =IFERROR(AVERAGEIFS(F4:F18,$C$4:$C$18,">0"),0) -> 0

Sheet Punto de Equilibrio
A1: Punto de Equilibrio Mensual
A3: Total costos fijos mensuales | B3: ='Costos Fijos'!B3 -> 1765000
A4: Margen de contribución promedio por milanesa | B4: ='Precios y Márgenes'!D20 -> 0
A6: MILANESAS A VENDER POR MES para cubrir costos fijos | B6: =IF(B4<=0,"N/D",ROUNDUP(B3/B4,0)) -> N/D
A7: ...equivalente por día (26 días/mes) | B7: =IF(B6="N/D","N/D",ROUNDUP(B6/26,0)) -> N/D
A10: Este cálculo usa el margen de contribución PROMEDIO de las recetas con precio cargado en 'Precios y Márgenes'. Si el margen promedio es negativo o cero, no hay punto de equilibrio posible con los precios actuales.
